nohup: ignoring input
Traceback (most recent call last):
  File "/home/kjablonk/anaconda3/envs/replication_study/lib/python3.8/runpy.py", line 194, in _run_module_as_main
    return _run_code(code, main_globals, None,
  File "/home/kjablonk/anaconda3/envs/replication_study/lib/python3.8/runpy.py", line 87, in _run_code
    exec(code, run_globals)
  File "/home/kjablonk/documents/replication_study/selfies_ga_nn_replication/experiments/experiment_8/ga/core_ga.py", line 261, in <module>
    main()
  File "/home/kjablonk/anaconda3/envs/replication_study/lib/python3.8/site-packages/click/core.py", line 829, in __call__
    return self.main(*args, **kwargs)
  File "/home/kjablonk/anaconda3/envs/replication_study/lib/python3.8/site-packages/click/core.py", line 782, in main
    rv = self.invoke(ctx)
  File "/home/kjablonk/anaconda3/envs/replication_study/lib/python3.8/site-packages/click/core.py", line 1066, in invoke
    return ctx.invoke(self.callback, **ctx.params)
  File "/home/kjablonk/anaconda3/envs/replication_study/lib/python3.8/site-packages/click/core.py", line 610, in invoke
    return callback(*args, **kwargs)
  File "/home/kjablonk/documents/replication_study/selfies_ga_nn_replication/experiments/experiment_8/ga/core_ga.py", line 176, in main
    os.mkdir(beta_dir)
FileExistsError: [Errno 17] File exists: '/home/kjablonk/documents/replication_study/selfies_ga_nn_replication/experiments/experiment_8/ga/results_beta_100'
